<?xml version="1.0" ?>
<sdf version="1.5">
  <model name="robot">
    <pose>0 0 0.180 0 0 0</pose>
    <static>false</static>
    <link name="base_link">
      <inertial>
        <mass>14.0</mass>
        <inertia>
          <ixx>0.147116667</ixx>
          <ixy>0.0</ixy>
          <ixz>0.0</ixz>
          <iyy>0.334951167</iyy>
          <iyz>0.0</iyz>
          <izz>0.3978345</izz>
        </inertia>
      </inertial>
      <collision name="base_collision">
        <geometry>
          <box>
            <size>0.501 0.300 0.19</size>
          </box>
        </geometry>
      </collision>
      <visual name="base_visual">
        <geometry>
          <mesh>
            <uri>model://robot_p3at/meshes/chassis.dae</uri>
          </mesh>
        </geometry>
      </visual>
    </link>
    <link name="right_front_wheel">
      <pose>0.125 -0.201 -0.06 1.5707 0 0</pose>

      <inertial>
        <mass>1.5</mass>
        <inertia>
          <ixx>0.005240625</ixx>
          <iyy>0.005240625</iyy>
          <izz>0.009075</izz>
          <ixy>0</ixy>
          <ixz>0</ixz>
          <iyz>0</iyz>
        </inertia>
      </inertial>

      <collision name="collision">
        <geometry>
          <cylinder>
            <radius>0.110</radius>
            <length>0.075</length>
          </cylinder>
        </geometry>
        <surface>
          <friction>
            <ode>
              <mu>1</mu>
              <mu2>1</mu2>

            </ode>
          </friction>
        </surface>
      </collision>
      <visual name="visual">
        <geometry>
          <mesh>
            <uri>model://robot_p3at/meshes/wheel.dae</uri>
          </mesh>
        </geometry>
      </visual>
    </link>
    <link name="left_front_wheel">
      <pose>0.125 0.201 -0.06 1.5707 0 0</pose>

      <inertial>
        <mass>1.5</mass>
        <inertia>
          <ixx>0.005240625</ixx>
          <iyy>0.005240625</iyy>
          <izz>0.009075</izz>
          <ixy>0</ixy>
          <ixz>0</ixz>
          <iyz>0</iyz>
        </inertia>
      </inertial>

      <collision name="collision">
        <geometry>
          <cylinder>
            <radius>0.110</radius>
            <length>0.075</length>
          </cylinder>
        </geometry>
        <surface>
          <friction>
            <ode>
              <mu>1</mu>
              <mu2>1</mu2>

            </ode>
          </friction>
        </surface>
      </collision>
      <visual name="visual">
        <geometry>
          <mesh>
            <uri>model://robot_p3at/meshes/wheel.dae</uri>
          </mesh>
        </geometry>
      </visual>
    </link>
    <link name="right_rear_wheel">
      <pose>-0.125 -0.201 -0.06 1.5707 0 0</pose>

      <inertial>
        <mass>1.5</mass>
        <inertia>
          <ixx>0.005240625</ixx>
          <iyy>0.005240625</iyy>
          <izz>0.009075</izz>
          <ixy>0</ixy>
          <ixz>0</ixz>
          <iyz>0</iyz>
        </inertia>
      </inertial>

      <collision name="collision">
        <geometry>
          <cylinder>
            <radius>0.110</radius>
            <length>0.075</length>
          </cylinder>
        </geometry>
        <surface>
          <friction>
            <ode>
              <mu>1</mu>
              <mu2>1</mu2>
            </ode>
          </friction>
        </surface>
      </collision>
      <visual name="visual">
        <geometry>
          <mesh>
            <uri>model://robot_p3at/meshes/wheel.dae</uri>
          </mesh>
        </geometry>
      </visual>
    </link>
    <link name="left_rear_wheel">
      <pose>-0.125 0.201 -0.06 1.5707 0 0</pose>

      <inertial>
        <mass>1.5</mass>
        <inertia>
          <ixx>0.005240625</ixx>
          <iyy>0.005240625</iyy>
          <izz>0.009075</izz>
          <ixy>0</ixy>
          <ixz>0</ixz>
          <iyz>0</iyz>
        </inertia>
      </inertial>

      <collision name="collision">
        <geometry>
          <cylinder>
            <radius>0.110</radius>
            <length>0.075</length>
          </cylinder>
        </geometry>
        <surface>
          <friction>
            <ode>
              <mu>1</mu>
              <mu2>1</mu2>
            </ode>
          </friction>
        </surface>
      </collision>
      <visual name="visual">
        <geometry>
          <mesh>
            <uri>model://robot_p3at/meshes/wheel.dae</uri>
          </mesh>
        </geometry>
      </visual>
    </link>
    <joint type="revolute" name="right_front">
      <pose>0 0 0 0 0 0</pose>
      <child>right_front_wheel</child>
      <parent>base_link</parent>
      <axis>
        <xyz>0 1 0</xyz>
        <use_parent_model_frame>true</use_parent_model_frame>
      </axis>
    </joint>
    <joint type="revolute" name="right_rear">
      <pose>0 0 0 0 0 0</pose>
      <child>right_rear_wheel</child>
      <parent>base_link</parent>
      <axis>
        <xyz>0 1 0</xyz>
        <use_parent_model_frame>true</use_parent_model_frame>
      </axis>
    </joint>
    <joint type="revolute" name="left_front">
      <pose>0 0 0 0 0 0</pose>
      <child>left_front_wheel</child>
      <parent>base_link</parent>
      <axis>
        <xyz>0 1 0</xyz>
        <use_parent_model_frame>true</use_parent_model_frame>
      </axis>
    </joint>
    <joint type="revolute" name="left_rear">
      <pose>0 0 0 0 0 0</pose>
      <child>left_rear_wheel</child>
      <parent>base_link</parent>
      <axis>
        <xyz>0 1 0</xyz>
        <use_parent_model_frame>true</use_parent_model_frame>
      </axis>
    </joint>

    <link name="camera_link">
      <pose>0.1 0 0.22 0 0 0</pose>
      <audio_sink /> <!-- Camera and microphone should be combined -->
      <inertial>
        <mass>0.1</mass>
        <inertia>
          <ixx>0.000166667</ixx>
          <iyy>0.000166667</iyy>
          <izz>0.000166667</izz>
        </inertia>
      </inertial>
      <collision name="collision-box">
        <pose>-0.01 0 0 0 0 0</pose>
        <geometry>
          <box>
            <size>0.08 0.1 0.1</size>
          </box>
        </geometry>
      </collision>
      <collision name="collision-lens">
        <pose>0.04 0 0 0 1.57 0</pose>
        <geometry>
          <cylinder>
            <radius>0.03</radius>
            <length>0.02</length>
          </cylinder>
        </geometry>
      </collision>
      <visual name="visual-box">
        <pose>-0.01 0 0 0 0 0</pose>
        <geometry>
          <box>
            <size>0.08 0.1 0.1</size>
          </box>
        </geometry>
        <material>
          <ambient>0.3 0.3 0.3 1</ambient>
          <diffuse>0.7 0.7 0.7 1</diffuse>
          <specular>0.1 0.1 0.1 1</specular>
          <emissive>0 0 0 0</emissive>
        </material>
      </visual>
      <visual name="visual-lens">
        <pose>0.04 0 0 0 1.57 0</pose>
        <geometry>
          <cylinder>
            <radius>0.03</radius>
            <length>0.02</length>
          </cylinder>
        </geometry>
        <material>
          <ambient>0 0 0 1</ambient>
          <diffuse>0 0 0 1</diffuse>
          <specular>0.1 0.1 0.1 1</specular>
          <emissive>0 0 0 0</emissive>
        </material>
      </visual>
<!-- RGB CAMERA --> 
      <sensor type="camera" name="camera">
        <update_rate>20</update_rate>
        <visualize>false</visualize>
        <camera name="camera">
          <horizontal_fov>1.047</horizontal_fov>
          <image>
            <width>320</width>
            <height>240</height>
            <format>R8G8B8</format>
          </image>
          <clip>
            <near>0.1</near>
            <far>100</far>
          </clip>

          <noise>
            <type>gaussian</type>
            <mean>0.0</mean>
            <stddev>0.007</stddev>
          </noise>
        </camera>
        <plugin name="camera_controller" filename="libgazebo_ros_camera.so">
          <alwaysOn>true</alwaysOn>
          <updateRate>0.0</updateRate>
          <cameraName>camera/rgb</cameraName>
          <imageTopicName>image_raw</imageTopicName>
          <cameraInfoTopicName>camera_info</cameraInfoTopicName>
          <frameName>camera_link</frameName>
          <hackBaseline>0.07</hackBaseline>
          <distortionK1>0.0</distortionK1>
          <distortionK2>0.0</distortionK2>
          <distortionK3>0.0</distortionK3>
          <distortionT1>0.0</distortionT1>
          <distortionT2>0.0</distortionT2>
        </plugin>
      </sensor>
<!-- THERMAL CAMERA --> 
      <sensor type="camera" name="thermal_camera_sensor">
        <update_rate>10</update_rate>
        <camera name="camera_ros_thermal">
          <horizontal_fov>1.047</horizontal_fov>
          <image>
            <width>160</width>
            <height>120</height>
            <format>R8G8B8</format>
          </image>
          <clip>
            <near>0.1</near>
            <far>100</far>
          </clip>

        </camera>
        <plugin name="thermal_camera_controller" 
                filename="libgazebo_ros_thermal_camera_pink.so">
          <alwaysOn>true</alwaysOn>
          <updateRate>10</updateRate>
          <imageTopicName>camera/thermal/image_raw</imageTopicName>
          <cameraInfoTopicName>camera/thermal/camera_info</cameraInfoTopicName>
          <frameName>camera_link</frameName>
<!--          <interface:camera name="thermal_camera_iface" /> -->
        </plugin>
      </sensor> 
    </link>
    <joint name="camera_joint" type="revolute">
      <parent>base_link</parent>
      <child>camera_link</child>
      <pose>0 0 0 0 0 0</pose>
      <axis>
        <xyz>0 0 1</xyz>
        <limit>
          <lower>0</lower>
          <upper>0</upper>
        </limit>
      </axis>
    </joint>

    <link name="hokuyo_link">
      <pose>0.1 0 0.135 0 0 0</pose>
      <inertial>
        <mass>0.1</mass>
        <inertia>
          <ixx>0.6205208333e-04</ixx>
          <iyy>0.6205208333e-04</iyy>
          <izz>4.1927083333e-05</izz>
        </inertia>
      </inertial>
      <visual name="visual-base">
        <pose>0 0 -0.0145 0 0 0</pose>
        <geometry>
          <box>
            <size>0.05 0.05 0.041</size>
          </box>
        </geometry>
        <material>
          <ambient>0.3 0.3 0.3 1</ambient>
          <diffuse>0.7 0.7 0.7 1</diffuse>
          <specular>0.1 0.1 0.1 1</specular>
          <emissive>0 0 0 0</emissive>
        </material>
      </visual>
      <visual name="visual-top">
        <pose>0 0 0.0205 0 0 0</pose>
        <geometry>
          <cylinder>
            <radius>0.021</radius>
            <length>0.029</length>
          </cylinder>
        </geometry>
        <material>
          <ambient>0 0 0 1</ambient>
          <diffuse>0 0 0 1</diffuse>
          <specular>0.1 0.1 0.1 1</specular>
          <emissive>0 0 0 0</emissive>
        </material>
      </visual>
      <visual name="visual-top-back">
        <pose>-0.02 0 0.019 0 0 0</pose>
        <geometry>
          <box>
            <size>0.01 0.01 0.025</size>
          </box>
        </geometry>
        <material>
          <ambient>0.1 0.1 0.1 1</ambient>
          <diffuse>0.3 0.3 0.3 1</diffuse>
          <specular>0.1 0.1 0.1 1</specular>
          <emissive>0 0 0 0</emissive>
        </material>
      </visual>
      <collision name="collision-base">
        <pose>0 0 -0.0145 0 0 0</pose>
        <geometry>
          <box>
            <size>0.05 0.05 0.041</size>
          </box>
        </geometry>
      </collision>
      <collision name="collision-top">
        <pose>0 0 0.0205 0 0 0</pose>
        <geometry>
          <cylinder>
            <radius>0.021</radius>
            <length>0.029</length>
          </cylinder>
        </geometry>
      </collision>
      <sensor type="ray" name="lms200">
        <always_on>true</always_on>
        <update_rate>30</update_rate>
        <pose>0 0 0.01815 0 0 0</pose> <!-- From URG04LX Spec -->
        <visualize>false</visualize>
        <ray>
          <scan>
            <horizontal>
		          <samples>181</samples>			<!-- 1040!!! -->
		          <resolution>1</resolution>
		          <min_angle>-1.570796</min_angle> <!-- 90deg: -1.570796 -->
		          <max_angle>1.570796</max_angle>  <!-- 90deg: 1.570796  -->
            </horizontal>
          </scan>
          <range>
            <min>0.1</min>
            <max>30</max> <!-- From URG04LX Spec -->
            <resolution>0.001</resolution> <!-- From URG04LX Spec -->
          </range>
        </ray>
        <plugin name="gazebo_ros_hokuyo_controller" filename="libgazebo_ros_ray_sensor.so">
            <ros>                
              <argument>~/out:=scan</argument>
            </ros>
            <output_type>sensor_msgs/LaserScan</output_type>
        </plugin>
      </sensor>
    </link>
    <joint name="hokuyo_joint" type="revolute">
      <parent>base_link</parent>
      <child>hokuyo_link</child>
      <pose>0 0 0 0 0 0</pose>
      <axis>
        <xyz>0 0 1</xyz>
        <limit>
          <lower>0</lower>
          <upper>0</upper>
        </limit>
      </axis>
    </joint>
    
    <plugin name='skid_steer_drive' filename='libgazebo_ros_diff_drive.so'>
        <!-- Update rate -->
        <update_rate>500</update_rate>

        <!-- Number of wheel pairs -->
        <num_wheel_pairs>2</num_wheel_pairs>
        
        <!-- wheels0 -->
        <left_joint>left_front</left_joint>
        <right_joint>right_front</right_joint>

        <!-- wheels1-->
        <left_joint>left_rear</left_joint>
        <right_joint>right_rear</right_joint>

        <!-- kinematics -->
        <wheel_separation>0.4</wheel_separation>
        <wheel_separation>0.4</wheel_separation>

        <wheel_diameter>0.215</wheel_diameter>
        <wheel_diameter>0.215</wheel_diameter>

        <!-- limits -->
        <max_wheel_torque>200</max_wheel_torque>
        <max_wheel_acceleration>1.0</max_wheel_acceleration>

        <!-- output -->
        <publish_odom>true</publish_odom>
        <publish_odom_tf>true</publish_odom_tf>
        <publish_wheel_tf>true</publish_wheel_tf>

        <odometry_frame>odom</odometry_frame>
        <robot_base_frame>base_link</robot_base_frame>

      </plugin>

    <plugin name="p3at_joint_state" filename="libgazebo_ros_joint_state_publisher.so">
      <ros>
        <remapping>out:=joint_states</remapping>
      </ros>
      <update_rate>30</update_rate>
      <joint_name>left_front</joint_name>
      <joint_name>right_front</joint_name>
      <joint_name>left_rear</joint_name>
      <joint_name>right_rear</joint_name>
    </plugin>   

    <plugin name="gazebo_ros_control" filename="libgazebo_ros_control.so">
      <robotSimType>gazebo_ros_control/DefaultRobotHWSim</robotSimType>
    </plugin>

  </model>
</sdf>
